Workbook

Sheet Candidates
A1: CandidateID | B1: Name | C1: JobOpeningID | D1: Source | E1: Recruiter | F1: ApplicationDate | G1: RecruiterReviewDate | H1: ScreeningDate | I1: InterviewScheduledDate | J1: InterviewCompletedDate | K1: OfferDate | L1: OfferResponse | M1: OfferResponseDate | N1: BackgroundCheckDate | O1: HireDate | P1: CurrentStage | Q1: FinalStatus | R1: RejectionStage | S1: RejectionReason | U1: Gap_F_G | V1: Gap_G_H | W1: Gap_H_I | X1: Gap_I_J | Y1: Gap_J_K | Z1: Gap_K_M | AA1: Gap_M_N | AB1: Gap_N_O
A2: CAND-0001 | B2: Hayden Jackson | C2: JO-01 | D2: LinkedIn | E2: J. Alvarez | F2: 46080 | G2: 46085 | P2: Rejected | Q2: Rejected | R2: Recruiter Review | S2: Resume mismatch | U2: =IF(AND(F2<>"",G2<>""),G2-F2,"") -> 5 | V2: =IF(AND(G2<>"",H2<>""),H2-G2,"") | W2: =IF(AND(H2<>"",I2<>""),I2-H2,"") | X2: =IF(AND(I2<>"",J2<>""),J2-I2,"") | Y2: =IF(AND(J2<>"",K2<>""),K2-J2,"") | Z2: =IF(AND(K2<>"",M2<>""),M2-K2,"") | AA2: =IF(AND(M2<>"",N2<>""),N2-M2,"") | AB2: =IF(AND(N2<>"",O2<>""),O2-N2,"")
A3: CAND-0002 | B3: Taylor Garcia | C3: JO-01 | D3: LinkedIn | E3: J. Alvarez | F3: 46113 | G3: 46118 | H3: 46124 | I3: 46129 | J3: 46133 | K3: 46136 | L3: Accepted | M3: 46140 | N3: 46148 | O3: 46151 | P3: Hired | Q3: Hired | U3: =IF(AND(F3<>"",G3<>""),G3-F3,"") -> 5 | V3: =IF(AND(G3<>"",H3<>""),H3-G3,"") -> 6 | W3: =IF(AND(H3<>"",I3<>""),I3-H3,"") -> 5 | X3: =IF(AND(I3<>"",J3<>""),J3-I3,"") -> 4 | Y3: =IF(AND(J3<>"",K3<>""),K3-J3,"") -> 3 | Z3: =IF(AND(K3<>"",M3<>""),M3-K3,"") -> 4 | AA3: =IF(AND(M3<>"",N3<>""),N3-M3,"") -> 8 | AB3: =IF(AND(N3<>"",O3<>""),O3-N3,"") -> 3
A4: CAND-0003 | B4: Sydney Brown | C4: JO-01 | D4: LinkedIn | E4: J. Alvarez | F4: 46078 | G4: 46081 | H4: 46087 | I4: 46104 | J4: 46108 | P4: Rejected | Q4: Rejected | R4: Interview | S4: Failed technical assessment | U4: =IF(AND(F4<>"",G4<>""),G4-F4,"") -> 3 | V4: =IF(AND(G4<>"",H4<>""),H4-G4,"") -> 6 | W4: =IF(AND(H4<>"",I4<>""),I4-H4,"") -> 17 | X4: =IF(AND(I4<>"",J4<>""),J4-I4,"") -> 4 | Y4: =IF(AND(J4<>"",K4<>""),K4-J4,"") | Z4: =IF(AND(K4<>"",M4<>""),M4-K4,"") | AA4: =IF(AND(M4<>"",N4<>""),N4-M4,"") | AB4: =IF(AND(N4<>"",O4<>""),O4-N4,"")
A5: CAND-0004 | B5: Elliot Taylor | C5: JO-01 | D5: Indeed | E5: J. Alvarez | F5: 46065 | G5: 46067 | H5: 46069 | I5: 46074 | J5: 46078 | K5: 46083 | L5: Accepted | M5: 46087 | N5: 46093 | O5: 46095 | P5: Hired | Q5: Hired | U5: =IF(AND(F5<>"",G5<>""),G5-F5,"") -> 2 | V5: =IF(AND(G5<>"",H5<>""),H5-G5,"") -> 2 | W5: =IF(AND(H5<>"",I5<>""),I5-H5,"") -> 5 | X5: =IF(AND(I5<>"",J5<>""),J5-I5,"") -> 4 | Y5: =IF(AND(J5<>"",K5<>""),K5-J5,"") -> 5 | Z5: =IF(AND(K5<>"",M5<>""),M5-K5,"") -> 4 | AA5: =IF(AND(M5<>"",N5<>""),N5-M5,"") -> 6 | AB5: =IF(AND(N5<>"",O5<>""),O5-N5,"") -> 2
A6: CAND-0005 | B6: Avery Roberts | C6: JO-01 | D6: Indeed | E6: J. Alvarez | F6: 46095 | G6: 46099 | H6: 46105 | I6: 46115 | J6: 46116 | K6: 46122 | L6: Declined | M6: 46128 | P6: Rejected | Q6: Rejected | R6: Offer | S6: Candidate withdrew | U6: =IF(AND(F6<>"",G6<>""),G6-F6,"") -> 4 | V6: =IF(AND(G6<>"",H6<>""),H6-G6,"") -> 6 | W6: =IF(AND(H6<>"",I6<>""),I6-H6,"") -> 10 | X6: =IF(AND(I6<>"",J6<>""),J6-I6,"") -> 1 | Y6: =IF(AND(J6<>"",K6<>""),K6-J6,"") -> 6 | Z6: =IF(AND(K6<>"",M6<>""),M6-K6,"") -> 6 | AA6: =IF(AND(M6<>"",N6<>""),N6-M6,"") | AB6: =IF(AND(N6<>"",O6<>""),O6-N6,"")
A7: CAND-0006 | B7: Blake Thomas | C7: JO-01 | D7: Indeed | E7: J. Alvarez | F7: 46155 | G7: 46159 | P7: Rejected | Q7: Rejected | R7: Recruiter Review | S7: Underqualified | U7: =IF(AND(F7<>"",G7<>""),G7-F7,"") -> 4 | V7: =IF(AND(G7<>"",H7<>""),H7-G7,"") | W7: =IF(AND(H7<>"",I7<>""),I7-H7,"") | X7: =IF(AND(I7<>"",J7<>""),J7-I7,"") | Y7: =IF(AND(J7<>"",K7<>""),K7-J7,"") | Z7: =IF(AND(K7<>"",M7<>""),M7-K7,"") | AA7: =IF(AND(M7<>"",N7<>""),N7-M7,"") | AB7: =IF(AND(N7<>"",O7<>""),O7-N7,"")
A8: CAND-0007 | B8: Bailey White | C8: JO-02 | D8: Indeed | E8: M. Chen | F8: 46163 | G8: 46168 | H8: 46171 | I8: 46188 | J8: 46189 | K8: 46193 | L8: Accepted | M8: 46197 | N8: 46206 | O8: 46211 | P8: Hired | Q8: Hired | U8: =IF(AND(F8<>"",G8<>""),G8-F8,"") -> 5 | V8: =IF(AND(G8<>"",H8<>""),H8-G8,"") -> 3 | W8: =IF(AND(H8<>"",I8<>""),I8-H8,"") -> 17 | X8: =IF(AND(I8<>"",J8<>""),J8-I8,"") -> 1 | Y8: =IF(AND(J8<>"",K8<>""),K8-J8,"") -> 4 | Z8: =IF(AND(K8<>"",M8<>""),M8-K8,"") -> 4 | AA8: =IF(AND(M8<>"",N8<>""),N8-M8,"") -> 9 | AB8: =IF(AND(N8<>"",O8<>""),O8-N8,"") -> 5
A9: CAND-0008 | B9: Finley Adams | C9: JO-02 | D9: Referral | E9: M. Chen | F9: 46195 | G9: 46196 | H9: 46198 | I9: 46202 | J9: 46203 | P9: Rejected | Q9: Rejected | R9: Interview | S9: Not selected - other candidate | U9: =IF(AND(F9<>"",G9<>""),G9-F9,"") -> 1 | V9: =IF(AND(G9<>"",H9<>""),H9-G9,"") -> 2 | W9: =IF(AND(H9<>"",I9<>""),I9-H9,"") -> 4 | X9: =IF(AND(I9<>"",J9<>""),J9-I9,"") -> 1 | Y9: =IF(AND(J9<>"",K9<>""),K9-J9,"") | Z9: =IF(AND(K9<>"",M9<>""),M9-K9,"") | AA9: =IF(AND(M9<>"",N9<>""),N9-M9,"") | AB9: =IF(AND(N9<>"",O9<>""),O9-N9,"")
A10: CAND-0009 | B10: Reagan Nguyen | C10: JO-02 | D10: University Fair | E10: M. Chen | F10: 46121 | G10: 46126 | H10: 46132 | I10: 46136 | J10: 46138 | K10: 46142 | L10: Accepted | M10: 46152 | N10: 46155 | O10: 46160 | P10: Hired | Q10: Hired | U10: =IF(AND(F10<>"",G10<>""),G10-F10,"") -> 5 | V10: =IF(AND(G10<>"",H10<>""),H10-G10,"") -> 6 | W10: =IF(AND(H10<>"",I10<>""),I10-H10,"") -> 4 | X10: =IF(AND(I10<>"",J10<>""),J10-I10,"") -> 2 | Y10: =IF(AND(J10<>"",K10<>""),K10-J10,"") -> 4 | Z10: =IF(AND(K10<>"",M10<>""),M10-K10,"") -> 10 | AA10: =IF(AND(M10<>"",N10<>""),N10-M10,"") -> 3 | AB10: =IF(AND(N10<>"",O10<>""),O10-N10,"") -> 5
A11: CAND-0010 | B11: Jordan Davis | C11: JO-02 | D11: Career Site | E11: M. Chen | F11: 46132 | G11: 46134 | P11: Rejected | Q11: Rejected | R11: Recruiter Review | S11: Salary expectations too high | U11: =IF(AND(F11<>"",G11<>""),G11-F11,"") -> 2 | V11: =IF(AND(G11<>"",H11<>""),H11-G11,"") | W11: =IF(AND(H11<>"",I11<>""),I11-H11,"") | X11: =IF(AND(I11<>"",J11<>""),J11-I11,"") | Y11: =IF(AND(J11<>"",K11<>""),K11-J11,"") | Z11: =IF(AND(K11<>"",M11<>""),M11-K11,"") | AA11: =IF(AND(M11<>"",N11<>""),N11-M11,"") | AB11: =IF(AND(N11<>"",O11<>""),O11-N11,"")
A12: CAND-0011 | B12: Riley Patel | C12: JO-02 | D12: Indeed | E12: M. Chen | F12: 46071 | G12: 46076 | H12: 46079 | I12: 46082 | J12: 46087 | K12: 46093 | L12: Accepted | M12: 46098 | N12: 46104 | O12: 46109 | P12: Hired | Q12: Hired | U12: =IF(AND(F12<>"",G12<>""),G12-F12,"") -> 5 | V12: =IF(AND(G12<>"",H12<>""),H12-G12,"") -> 3 | W12: =IF(AND(H12<>"",I12<>""),I12-H12,"") -> 3 | X12: =IF(AND(I12<>"",J12<>""),J12-I12,"") -> 5 | Y12: =IF(AND(J12<>"",K12<>""),K12-J12,"") -> 6 | Z12: =IF(AND(K12<>"",M12<>""),M12-K12,"") -> 5 | AA12: =IF(AND(M12<>"",N12<>""),N12-M12,"") -> 6 | AB12: =IF(AND(N12<>"",O12<>""),O12-N12,"") -> 5
A13: CAND-0012 | B13: Elliot Baker | C13: JO-02 | D13: Career Site | E13: M. Chen | F13: 46169 | G13: 46170 | H13: 46172 | I13: 46175 | J13: 46176 | P13: Rejected | Q13: Rejected | R13: Interview | S13: Interview no-show | U13: =IF(AND(F13<>"",G13<>""),G13-F13,"") -> 1 | V13: =IF(AND(G13<>"",H13<>""),H13-G13,"") -> 2 | W13: =IF(AND(H13<>"",I13<>""),I13-H13,"") -> 3 | X13: =IF(AND(I13<>"",J13<>""),J13-I13,"") -> 1 | Y13: =IF(AND(J13<>"",K13<>""),K13-J13,"") | Z13: =IF(AND(K13<>"",M13<>""),M13-K13,"") | AA13: =IF(AND(M13<>"",N13<>""),N13-M13,"") | AB13: =IF(AND(N13<>"",O13<>""),O13-N13,"")
A14: CAND-0013 | B14: Morgan Moore | C14: JO-02 | D14: LinkedIn | E14: M. Chen | F14: 46062 | G14: 46065 | P14: Rejected | Q14: Rejected | R14: Recruiter Review | S14: Underqualified | U14: =IF(AND(F14<>"",G14<>""),G14-F14,"") -> 3 | V14: =IF(AND(G14<>"",H14<>""),H14-G14,"") | W14: =IF(AND(H14<>"",I14<>""),I14-H14,"") | X14: =IF(AND(I14<>"",J14<>""),J14-I14,"") | Y14: =IF(AND(J14<>"",K14<>""),K14-J14,"") | Z14: =IF(AND(K14<>"",M14<>""),M14-K14,"") | AA14: =IF(AND(M14<>"",N14<>""),N14-M14,"") | AB14: =IF(AND(N14<>"",O14<>""),O14-N14,"")
A15: CAND-0014 | B15: Hayden Carter | C15: JO-02 | D15: LinkedIn | E15: M. Chen | F15: 46087 | G15: 46092 | H15: 46095 | I15: 46098 | J15: 46099 | K15: 46104 | L15: Accepted | M15: 46112 | N15: 46115 | O15: 46117 | P15: Hired | Q15: Hired | U15: =IF(AND(F15<>"",G15<>""),G15-F15,"") -> 5 | V15: =IF(AND(G15<>"",H15<>""),H15-G15,"") -> 3 | W15: =IF(AND(H15<>"",I15<>""),I15-H15,"") -> 3 | X15: =IF(AND(I15<>"",J15<>""),J15-I15,"") -> 1 | Y15: =IF(AND(J15<>"",K15<>""),K15-J15,"") -> 5 | Z15: =IF(AND(K15<>"",M15<>""),M15-K15,"") -> 8 | AA15: =IF(AND(M15<>"",N15<>""),N15-M15,"") -> 3 | AB15: =IF(AND(N15<>"",O15<>""),O15-N15,"") -> 2
A16: CAND-0015 | B16: Morgan Wright | C16: JO-02 | D16: Indeed | E16: M. Chen | F16: 46081 | G16: 46083 | H16: 46089 | I16: 46103 | J16: 46105 | K16: 46108 | L16: Accepted | M16: 46117 | N16: 46121 | O16: 46123 | P16: Hired | Q16: Hired | U16: =IF(AND(F16<>"",G16<>""),G16-F16,"") -> 2 | V16: =IF(AND(G16<>"",H16<>""),H16-G16,"") -> 6 | W16: =IF(AND(H16<>"",I16<>""),I16-H16,"") -> 14 | X16: =IF(AND(I16<>"",J16<>""),J16-I16,"") -> 2 | Y16: =IF(AND(J16<>"",K16<>""),K16-J16,"") -> 3 | Z16: =IF(AND(K16<>"",M16<>""),M16-K16,"") -> 9 | AA16: =IF(AND(M16<>"",N16<>""),N16-M16,"") -> 4 | AB16: =IF(AND(N16<>"",O16<>""),O16-N16,"") -> 2
A17: CAND-0016 | B17: Riley Jackson | C17: JO-02 | D17: LinkedIn | E17: M. Chen | F17: 46178 | G17: 46182 | H17: 46187 | I17: 46197 | J17: 46200 | K17: 46206 | L17: Accepted | M17: 46212 | N17: 46222 | O17: 46226 | P17: Hired | Q17: Hired | U17: =IF(AND(F17<>"",G17<>""),G17-F17,"") -> 4 | V17: =IF(AND(G17<>"",H17<>""),H17-G17,"") -> 5 | W17: =IF(AND(H17<>"",I17<>""),I17-H17,"") -> 10 | X17: =IF(AND(I17<>"",J17<>""),J17-I17,"") -> 3 | Y17: =IF(AND(J17<>"",K17<>""),K17-J17,"") -> 6 | Z17: =IF(AND(K17<>"",M17<>""),M17-K17,"") -> 6 | AA17: =IF(AND(M17<>"",N17<>""),N17-M17,"") -> 10 | AB17: =IF(AND(N17<>"",O17<>""),O17-N17,"") -> 4
A18: CAND-0017 | B18: Reese Johnson | C18: JO-02 | D18: Indeed | E18: M. Chen | F18: 46192 | G18: 46193 | H18: 46195 | P18: Rejected | Q18: Rejected | R18: Screening | S18: Compensation mismatch | U18: =IF(AND(F18<>"",G18<>""),G18-F18,"") -> 1 | V18: =IF(AND(G18<>"",H18<>""),H18-G18,"") -> 2 | W18: =IF(AND(H18<>"",I18<>""),I18-H18,"") | X18: =IF(AND(I18<>"",J18<>""),J18-I18,"") | Y18: =IF(AND(J18<>"",K18<>""),K18-J18,"") | Z18: =IF(AND(K18<>"",M18<>""),M18-K18,"") | AA18: =IF(AND(M18<>"",N18<>""),N18-M18,"") | AB18: =IF(AND(N18<>"",O18<>""),O18-N18,"")
A19: CAND-0018 | B19: Wren Perez | C19: JO-02 | D19: LinkedIn | E19: M. Chen | F19: 46184 | G19: 46185 | H19: 46187 | I19: 46190 | J19: 46191 | K19: 46198 | L19: Accepted | M19: 46203 | N19: 46206 | O19: 46211 | P19: Hired | Q19: Hired | U19: =IF(AND(F19<>"",G19<>""),G19-F19,"") -> 1 | V19: =IF(AND(G19<>"",H19<>""),H19-G19,"") -> 2 | W19: =IF(AND(H19<>"",I19<>""),I19-H19,"") -> 3 | X19: =IF(AND(I19<>"",J19<>""),J19-I19,"") -> 1 | Y19: =IF(AND(J19<>"",K19<>""),K19-J19,"") -> 7 | Z19: =IF(AND(K19<>"",M19<>""),M19-K19,"") -> 5 | AA19: =IF(AND(M19<>"",N19<>""),N19-M19,"") -> 3 | AB19: =IF(AND(N19<>"",O19<>""),O19-N19,"") -> 5
A20: CAND-0019 | B20: Adrian Young | C20: JO-02 | D20: Career Site | E20: M. Chen | F20: 46106 | G20: 46109 | H20: 46114 | I20: 46119 | J20: 46120 | P20: Rejected | Q20: Rejected | R20: Interview | S20: Interview no-show | U20: =IF(AND(F20<>"",G20<>""),G20-F20,"") -> 3 | V20: =IF(AND(G20<>"",H20<>""),H20-G20,"") -> 5 | W20: =IF(AND(H20<>"",I20<>""),I20-H20,"") -> 5 | X20: =IF(AND(I20<>"",J20<>""),J20-I20,"") -> 1 | Y20: =IF(AND(J20<>"",K20<>""),K20-J20,"") | Z20: =IF(AND(K20<>"",M20<>""),M20-K20,"") | AA20: =IF(AND(M20<>"",N20<>""),N20-M20,"") | AB20: =IF(AND(N20<>"",O20<>""),O20-N20,"")
A21: CAND-0020 | B21: Sam Kim | C21: JO-02 | D21: Referral | E21: M. Chen | F21: 46183 | G21: 46186 | P21: Rejected | Q21: Rejected | R21: Recruiter Review | S21: Resume mismatch | U21: =IF(AND(F21<>"",G21<>""),G21-F21,"") -> 3 | V21: =IF(AND(G21<>"",H21<>""),H21-G21,"") | W21: =IF(AND(H21<>"",I21<>""),I21-H21,"") | X21: =IF(AND(I21<>"",J21<>""),J21-I21,"") | Y21: =IF(AND(J21<>"",K21<>""),K21-J21,"") | Z21: =IF(AND(K21<>"",M21<>""),M21-K21,"") | AA21: =IF(AND(M21<>"",N21<>""),N21-M21,"") | AB21: =IF(AND(N21<>"",O21<>""),O21-N21,"")
A22: CAND-0021 | B22: Elliot Clark | C22: JO-03 | D22: LinkedIn | E22: J. Alvarez | F22: 46193 | G22: 46196 | H22: 46202 | P22: Rejected | Q22: Rejected | R22: Screening | S22: Poor culture fit signal | U22: =IF(AND(F22<>"",G22<>""),G22-F22,"") -> 3 | V22: =IF(AND(G22<>"",H22<>""),H22-G22,"") -> 6 | W22: =IF(AND(H22<>"",I22<>""),I22-H22,"") | X22: =IF(AND(I22<>"",J22<>""),J22-I22,"") | Y22: =IF(AND(J22<>"",K22<>""),K22-J22,"") | Z22: =IF(AND(K22<>"",M22<>""),M22-K22,"") | AA22: =IF(AND(M22<>"",N22<>""),N22-M22,"") | AB22: =IF(AND(N22<>"",O22<>""),O22-N22,"")
A23: CAND-0022 | B23: Dakota Brown | C23: JO-03 | D23: Career Site | E23: J. Alvarez | F23: 46088 | G23: 46091 | P23: Rejected | Q23: Rejected | R23: Recruiter Review | S23: Underqualified | U23: =IF(AND(F23<>"",G23<>""),G23-F23,"") -> 3 | V23: =IF(AND(G23<>"",H23<>""),H23-G23,"") | W23: =IF(AND(H23<>"",I23<>""),I23-H23,"") | X23: =IF(AND(I23<>"",J23<>""),J23-I23,"") | Y23: =IF(AND(J23<>"",K23<>""),K23-J23,"") | Z23: =IF(AND(K23<>"",M23<>""),M23-K23,"") | AA23: =IF(AND(M23<>"",N23<>""),N23-M23,"") | AB23: =IF(AND(N23<>"",O23<>""),O23-N23,"")
A24: CAND-0023 | B24: Cameron Harris | C24: JO-03 | D24: LinkedIn | E24: J. Alvarez | F24: 46107 | G24: 46110 | H24: 46114 | I24: 46124 | J24: 46130 | K24: 46135 | L24: Declined | M24: 46137 | P24: Rejected | Q24: Rejected | R24: Offer | S24: Accepted competing offer | U24: =IF(AND(F24<>"",G24<>""),G24-F24,"") -> 3 | V24: =IF(AND(G24<>"",H24<>""),H24-G24,"") -> 4 | W24: =IF(AND(H24<>"",I24<>""),I24-H24,"") -> 10 | X24: =IF(AND(I24<>"",J24<>""),J24-I24,"") -> 6 | Y24: =IF(AND(J24<>"",K24<>""),K24-J24,"") -> 5 | Z24: =IF(AND(K24<>"",M24<>""),M24-K24,"") -> 2 | AA24: =IF(AND(M24<>"",N24<>""),N24-M24,"") | AB24: =IF(AND(N24<>"",O24<>""),O24-N24,"")
A25: CAND-0024 | B25: Emerson Anderson | C25: JO-03 | D25: Indeed | E25: J. Alvarez | F25: 46195 | G25: 46199 | H25: 46201 | P25: Rejected | Q25: Rejected | R25: Screening | S25: Poor culture fit signal | U25: =IF(AND(F25<>"",G25<>""),G25-F25,"") -> 4 | V25: =IF(AND(G25<>"",H25<>""),H25-G25,"") -> 2 | W25: =IF(AND(H25<>"",I25<>""),I25-H25,"") | X25: =IF(AND(I25<>"",J25<>""),J25-I25,"") | Y25: =IF(AND(J25<>"",K25<>""),K25-J25,"") | Z25: =IF(AND(K25<>"",M25<>""),M25-K25,"") | AA25: =IF(AND(M25<>"",N25<>""),N25-M25,"") | AB25: =IF(AND(N25<>"",O25<>""),O25-N25,"")
A26: CAND-0025 | B26: Cameron Roberts | C26: JO-03 | D26: LinkedIn | E26: J. Alvarez | F26: 46148 | G26: 46153 | H26: 46158 | I26: 46168 | J26: 46170 | K26: 46178 | L26: Accepted | M26: 46181 | N26: 46190 | O26: 46193 | P26: Hired | Q26: Hired | U26: =IF(AND(F26<>"",G26<>""),G26-F26,"") -> 5 | V26: =IF(AND(G26<>"",H26<>""),H26-G26,"") -> 5 | W26: =IF(AND(H26<>"",I26<>""),I26-H26,"") -> 10 | X26: =IF(AND(I26<>"",J26<>""),J26-I26,"") -> 2 | Y26: =IF(AND(J26<>"",K26<>""),K26-J26,"") -> 8 | Z26: =IF(AND(K26<>"",M26<>""),M26-K26,"") -> 3 | AA26: =IF(AND(M26<>"",N26<>""),N26-M26,"") -> 9 | AB26: =IF(AND(N26<>"",O26<>""),O26-N26,"") -> 3
A27: CAND-0026 | B27: Rowan Anderson | C27: JO-03 | D27: University Fair | E27: J. Alvarez | F27: 46099 | G27: 46103 | P27: Rejected | Q27: Rejected | R27: Recruiter Review | S27: Salary expectations too high | U27: =IF(AND(F27<>"",G27<>""),G27-F27,"") -> 4 | V27: =IF(AND(G27<>"",H27<>""),H27-G27,"") | W27: =IF(AND(H27<>"",I27<>""),I27-H27,"") | X27: =IF(AND(I27<>"",J27<>""),J27-I27,"") | Y27: =IF(AND(J27<>"",K27<>""),K27-J27,"") | Z27: =IF(AND(K27<>"",M27<>""),M27-K27,"") | AA27: =IF(AND(M27<>"",N27<>""),N27-M27,"") | AB27: =IF(AND(N27<>"",O27<>""),O27-N27,"")
A28: CAND-0027 | B28: Sydney Scott | C28: JO-03 | D28: Career Site | E28: J. Alvarez | F28: 46117 | G28: 46120 | H28: 46122 | I28: 46139 | J28: 46141 | K28: 46147 | L28: Accepted | M28: 46154 | N28: 46160 | O28: 46163 | P28: Hired | Q28: Hired | U28: =IF(AND(F28<>"",G28<>""),G28-F28,"") -> 3 | V28: =IF(AND(G28<>"",H28<>""),H28-G28,"") -> 2 | W28: =IF(AND(H28<>"",I28<>""),I28-H28,"") -> 17 | X28: =IF(AND(I28<>"",J28<>""),J28-I28,"") -> 2 | Y28: =IF(AND(J28<>"",K28<>""),K28-J28,"") -> 6 | Z28: =IF(AND(K28<>"",M28<>""),M28-K28,"") -> 7 | AA28: =IF(AND(M28<>"",N28<>""),N28-M28,"") -> 6 | AB28: =IF(AND(N28<>"",O28<>""),O28-N28,"") -> 3
A29: CAND-0028 | B29: Harper Walker | C29: JO-03 | D29: LinkedIn | E29: J. Alvarez | F29: 46071 | G29: 46074 | H29: 46080 | I29: 46084 | J29: 46085 | K29: 46090 | L29: Accepted | M29: 46094 | N29: 46101 | P29: Rejected | Q29: Rejected | R29: Background Check | S29: Failed background check | U29: =IF(AND(F29<>"",G29<>""),G29-F29,"") -> 3 | V29: =IF(AND(G29<>"",H29<>""),H29-G29,"") -> 6 | W29: =IF(AND(H29<>"",I29<>""),I29-H29,"") -> 4 | X29: =IF(AND(I29<>"",J29<>""),J29-I29,"") -> 1 | Y29: =IF(AND(J29<>"",K29<>""),K29-J29,"") -> 5 | Z29: =IF(AND(K29<>"",M29<>""),M29-K29,"") -> 4 | AA29: =IF(AND(M29<>"",N29<>""),N29-M29,"") -> 7 | AB29: =IF(AND(N29<>"",O29<>""),O29-N29,"")
A30: CAND-0029 | B30: Logan Hall | C30: JO-03 | D30: Indeed | E30: J. Alvarez | F30: 46134 | G30: 46138 | H30: 46144 | P30: Rejected | Q30: Rejected | R30: Screening | S30: Poor culture fit signal | U30: =IF(AND(F30<>"",G30<>""),G30-F30,"") -> 4 | V30: =IF(AND(G30<>"",H30<>""),H30-G30,"") -> 6 | W30: =IF(AND(H30<>"",I30<>""),I30-H30,"") | X30: =IF(AND(I30<>"",J30<>""),J30-I30,"") | Y30: =IF(AND(J30<>"",K30<>""),K30-J30,"") | Z30: =IF(AND(K30<>"",M30<>""),M30-K30,"") | AA30: =IF(AND(M30<>"",N30<>""),N30-M30,"") | AB30: =IF(AND(N30<>"",O30<>""),O30-N30,"")
A31: CAND-0030 | B31: Taylor Green | C31: JO-04 | D31: LinkedIn | E31: M. Chen | F31: 46191 | G31: 46193 | H31: 46195 | I31: 46199 | J31: 46205 | K31: 46212 | L31: Accepted | M31: 46218 | N31: 46226 | O31: 46230 | P31: Hired | Q31: Hired | U31: =IF(AND(F31<>"",G31<>""),G31-F31,"") -> 2 | V31: =IF(AND(G31<>"",H31<>""),H31-G31,"") -> 2 | W31: =IF(AND(H31<>"",I31<>""),I31-H31,"") -> 4 | X31: =IF(AND(I31<>"",J31<>""),J31-I31,"") -> 6 | Y31: =IF(AND(J31<>"",K31<>""),K31-J31,"") -> 7 | Z31: =IF(AND(K31<>"",M31<>""),M31-K31,"") -> 6 | AA31: =IF(AND(M31<>"",N31<>""),N31-M31,"") -> 8 | AB31: =IF(AND(N31<>"",O31<>""),O31-N31,"") -> 4
A32: CAND-0031 | B32: Drew Taylor | C32: JO-04 | D32: Referral | E32: M. Chen | F32: 46151 | G32: 46153 | H32: 46157 | I32: 46161 | J32: 46163 | K32: 46170 | L32: Accepted | M32: 46177 | N32: 46187 | O32: 46192 | P32: Hired | Q32: Hired | U32: =IF(AND(F32<>"",G32<>""),G32-F32,"") -> 2 | V32: =IF(AND(G32<>"",H32<>""),H32-G32,"") -> 4 | W32: =IF(AND(H32<>"",I32<>""),I32-H32,"") -> 4 | X32: =IF(AND(I32<>"",J32<>""),J32-I32,"") -> 2 | Y32: =IF(AND(J32<>"",K32<>""),K32-J32,"") -> 7 | Z32: =IF(AND(K32<>"",M32<>""),M32-K32,"") -> 7 | AA32: =IF(AND(M32<>"",N32<>""),N32-M32,"") -> 10 | AB32: =IF(AND(N32<>"",O32<>""),O32-N32,"") -> 5
A33: CAND-0032 | B33: Avery Patel | C33: JO-04 | D33: LinkedIn | E33: M. Chen | F33: 46139 | G33: 46140 | H33: 46143 | I33: 46156 | J33: 46157 | P33: Rejected | Q33: Rejected | R33: Interview | S33: Failed technical assessment | U33: =IF(AND(F33<>"",G33<>""),G33-F33,"") -> 1 | V33: =IF(AND(G33<>"",H33<>""),H33-G33,"") -> 3 | W33: =IF(AND(H33<>"",I33<>""),I33-H33,"") -> 13 | X33: =IF(AND(I33<>"",J33<>""),J33-I33,"") -> 1 | Y33: =IF(AND(J33<>"",K33<>""),K33-J33,"") | Z33: =IF(AND(K33<>"",M33<>""),M33-K33,"") | AA33: =IF(AND(M33<>"",N33<>""),N33-M33,"") | AB33: =IF(AND(N33<>"",O33<>""),O33-N33,"")
A34: CAND-0033 | B34: Casey Adams | C34: JO-04 | D34: Referral | E34: M. Chen | F34: 46201 | G34: 46203 | H34: 46208 | I34: 46218 | J34: 46222 | P34: Rejected | Q34: Rejected | R34: Interview | S34: Interview no-show | U34: =IF(AND(F34<>"",G34<>""),G34-F34,"") -> 2 | V34: =IF(AND(G34<>"",H34<>""),H34-G34,"") -> 5 | W34: =IF(AND(H34<>"",I34<>""),I34-H34,"") -> 10 | X34: =IF(AND(I34<>"",J34<>""),J34-I34,"") -> 4 | Y34: =IF(AND(J34<>"",K34<>""),K34-J34,"") | Z34: =IF(AND(K34<>"",M34<>""),M34-K34,"") | AA34: =IF(AND(M34<>"",N34<>""),N34-M34,"") | AB34: =IF(AND(N34<>"",O34<>""),O34-N34,"")
A35: CAND-0034 | B35: Adrian Adams | C35: JO-04 | D35: LinkedIn | E35: M. Chen | F35: 46117 | G35: 46118 | H35: 46123 | I35: 46127 | J35: 46132 | K35: 46139 | L35: Accepted | M35: 46147 | N35: 46157 | O35: 46162 | P35: Hired | Q35: Hired | U35: =IF(AND(F35<>"",G35<>""),G35-F35,"") -> 1 | V35: =IF(AND(G35<>"",H35<>""),H35-G35,"") -> 5 | W35: =IF(AND(H35<>"",I35<>""),I35-H35,"") -> 4 | X35: =IF(AND(I35<>"",J35<>""),J35-I35,"") -> 5 | Y35: =IF(AND(J35<>"",K35<>""),K35-J35,"") -> 7 | Z35: =IF(AND(K35<>"",M35<>""),M35-K35,"") -> 8 | AA35: =IF(AND(M35<>"",N35<>""),N35-M35,"") -> 10 | AB35: =IF(AND(N35<>"",O35<>""),O35-N35,"") -> 5
A36: CAND-0035 | B36: Micah White | C36: JO-04 | D36: Indeed | E36: M. Chen | F36: 46124 | G36: 46129 | H36: 46132 | I36: 46146 | J36: 46149 | K36: 46156 | L36: Declined | M36: 46159 | P36: Rejected | Q36: Rejected | R36: Offer | S36: Accepted competing offer | U36: =IF(AND(F36<>"",G36<>""),G36-F36,"") -> 5 | V36: =IF(AND(G36<>"",H36<>""),H36-G36,"") -> 3 | W36: =IF(AND(H36<>"",I36<>""),I36-H36,"") -> 14 | X36: =IF(AND(I36<>"",J36<>""),J36-I36,"") -> 3 | Y36: =IF(AND(J36<>"",K36<>""),K36-J36,"") -> 7 | Z36: =IF(AND(K36<>"",M36<>""),M36-K36,"") -> 3 | AA36: =IF(AND(M36<>"",N36<>""),N36-M36,"") | AB36: =IF(AND(N36<>"",O36<>""),O36-N36,"")
A37: CAND-0036 | B37: Finley Wilson | C37: JO-04 | D37: Indeed | E37: M. Chen | F37: 46070 | G37: 46074 | H37: 46080 | I37: 46096 | J37: 46101 | K37: 46104 | L37: Accepted | M37: 46112 | N37: 46120 | O37: 46125 | P37: Hired | Q37: Hired | U37: =IF(AND(F37<>"",G37<>""),G37-F37,"") -> 4 | V37: =IF(AND(G37<>"",H37<>""),H37-G37,"") -> 6 | W37: =IF(AND(H37<>"",I37<>""),I37-H37,"") -> 16 | X37: =IF(AND(I37<>"",J37<>""),J37-I37,"") -> 5 | Y37: =IF(AND(J37<>"",K37<>""),K37-J37,"") -> 3 | Z37: =IF(AND(K37<>"",M37<>""),M37-K37,"") -> 8 | AA37: =IF(AND(M37<>"",N37<>""),N37-M37,"") -> 8 | AB37: =IF(AND(N37<>"",O37<>""),O37-N37,"") -> 5
A38: CAND-0037 | B38: Kendall Roberts | C38: JO-04 | D38: Indeed | E38: M. Chen | F38: 46193 | G38: 46198 | H38: 46203 | I38: 46213 | J38: 46216 | K38: 46222 | L38: Accepted | M38: 46226 | N38: 46231 | O38: 46233 | P38: Hired | Q38: Hired | U38: =IF(AND(F38<>"",G38<>""),G38-F38,"") -> 5 | V38: =IF(AND(G38<>"",H38<>""),H38-G38,"") -> 5 | W38: =IF(AND(H38<>"",I38<>""),I38-H38,"") -> 10 | X38: =IF(AND(I38<>"",J38<>""),J38-I38,"") -> 3 | Y38: =IF(AND(J38<>"",K38<>""),K38-J38,"") -> 6 | Z38: =IF(AND(K38<>"",M38<>""),M38-K38,"") -> 4 | AA38: =IF(AND(M38<>"",N38<>""),N38-M38,"") -> 5 | AB38: =IF(AND(N38<>"",O38<>""),O38-N38,"") -> 2
A39: CAND-0038 | B39: Harper Garcia | C39: JO-04 | D39: LinkedIn | E39: M. Chen | F39: 46163 | G39: 46165 | H39: 46168 | P39: Rejected | Q39: Rejected | R39: Screening | S39: Compensation mismatch | U39: =IF(AND(F39<>"",G39<>""),G39-F39,"") -> 2 | V39: =IF(AND(G39<>"",H39<>""),H39-G39,"") -> 3 | W39: =IF(AND(H39<>"",I39<>""),I39-H39,"") | X39: =IF(AND(I39<>"",J39<>""),J39-I39,"") | Y39: =IF(AND(J39<>"",K39<>""),K39-J39,"") | Z39: =IF(AND(K39<>"",M39<>""),M39-K39,"") | AA39: =IF(AND(M39<>"",N39<>""),N39-M39,"") | AB39: =IF(AND(N39<>"",O39<>""),O39-N39,"")
A40: CAND-0039 | B40: Blake Thomas | C40: JO-04 | D40: Referral | E40: M. Chen | F40: 46140 | G40: 46144 | H40: 46149 | I40: 46159 | J40: 46162 | P40: Rejected | Q40: Rejected | R40: Interview | S40: Not selected - other candidate | U40: =IF(AND(F40<>"",G40<>""),G40-F40,"") -> 4 | V40: =IF(AND(G40<>"",H40<>""),H40-G40,"") -> 5 | W40: =IF(AND(H40<>"",I40<>""),I40-H40,"") -> 10 | X40: =IF(AND(I40<>"",J40<>""),J40-I40,"") -> 3 | Y40: =IF(AND(J40<>"",K40<>""),K40-J40,"") | Z40: =IF(AND(K40<>"",M40<>""),M40-K40,"") | AA40: =IF(AND(M40<>"",N40<>""),N40-M40,"") | AB40: =IF(AND(N40<>"",O40<>""),O40-N40,"")
...

Sheet Job Openings
A1: JobOpeningID | B1: Title | C1: Department | D1: Recruiter | E1: Applicants | F1: Hired | G1: Status
A2: JO-01 | B2: Process Engineer II | C2: Manufacturing | D2: J. Alvarez | E2: =COUNTIF(Candidates!$C$2:$C$98,A2) -> 6 | F2: =COUNTIFS(Candidates!$C$2:$C$98,A2,Candidates!$Q$2:$Q$98,"Hired") -> 2 | G2: Open
A3: JO-02 | B3: Yield Engineer | C3: Manufacturing | D3: M. Chen | E3: =COUNTIF(Candidates!$C$2:$C$98,A3) -> 14 | F3: =COUNTIFS(Candidates!$C$2:$C$98,A3,Candidates!$Q$2:$Q$98,"Hired") -> 7 | G3: Open
A4: JO-03 | B4: Test Engineer | C4: Quality | D4: J. Alvarez | E4: =COUNTIF(Candidates!$C$2:$C$98,A4) -> 9 | F4: =COUNTIFS(Candidates!$C$2:$C$98,A4,Candidates!$Q$2:$Q$98,"Hired") -> 2 | G4: Open
A5: JO-04 | B5: Equipment Engineer | C5: Manufacturing | D5: M. Chen | E5: =COUNTIF(Candidates!$C$2:$C$98,A5) -> 10 | F5: =COUNTIFS(Candidates!$C$2:$C$98,A5,Candidates!$Q$2:$Q$98,"Hired") -> 5 | G5: Open
A6: JO-05 | B6: DFT Engineer | C6: Design | D6: J. Alvarez | E6: =COUNTIF(Candidates!$C$2:$C$98,A6) -> 6 | F6: =COUNTIFS(Candidates!$C$2:$C$98,A6,Candidates!$Q$2:$Q$98,"Hired") -> 3 | G6: Open
A7: JO-06 | B7: Quality Engineer | C7: Quality | D7: M. Chen | E7: =COUNTIF(Candidates!$C$2:$C$98,A7) -> 10 | F7: =COUNTIFS(Candidates!$C$2:$C$98,A7,Candidates!$Q$2:$Q$98,"Hired") -> 4 | G7: Open
A8: JO-07 | B8: Supply Chain Analyst | C8: Operations | D8: R. Thompson | E8: =COUNTIF(Candidates!$C$2:$C$98,A8) -> 14 | F8: =COUNTIFS(Candidates!$C$2:$C$98,A8,Candidates!$Q$2:$Q$98,"Hired") -> 7 | G8: Open
A9: JO-08 | B9: Software Engineer, Tools | C9: Engineering | D9: M. Chen | E9: =COUNTIF(Candidates!$C$2:$C$98,A9) -> 12 | F9: =COUNTIFS(Candidates!$C$2:$C$98,A9,Candidates!$Q$2:$Q$98,"Hired") -> 4 | G9: Open
A10: JO-09 | B10: Data Analyst, Ops | C10: Operations | D10: R. Thompson | E10: =COUNTIF(Candidates!$C$2:$C$98,A10) -> 7 | F10: =COUNTIFS(Candidates!$C$2:$C$98,A10,Candidates!$Q$2:$Q$98,"Hired") -> 1 | G10: Open
A11: JO-10 | B11: Manufacturing Technician | C11: Manufacturing | D11: S. Patel | E11: =COUNTIF(Candidates!$C$2:$C$98,A11) -> 9 | F11: =COUNTIFS(Candidates!$C$2:$C$98,A11,Candidates!$Q$2:$Q$98,"Hired") -> 4 | G11: Open

Sheet Metrics Dashboard
B2: Recruiting Funnel — KPI Dashboard
B3: All figures calculated live from the Candidates sheet via formula
B5: 1. Time-to-Hire (avg calendar days, Application -> Hire, Hired candidates only)
B6: Average Time-to-Hire (days) | D6: =SUMPRODUCT((Candidates!$Q$2:$Q$98="Hired")*(Candidates!$O$2:$O$98<>"")*(Candidates!$O$2:$O$98-Candidates!$F$2:$F$98))/SUMPRODUCT((Candidates!$Q$2:$Q$98="Hired")*(Candidates!$O$2:$O$98<>"")) -> 40.923077
B8: 2. Applicants per Opening
B9: Average applicants per opening | D9: =COUNTA(Candidates!$C$2:$C$98)/COUNTA('Job Openings'!$A$2:$A$11) -> 9.7 | E9: See Job Openings sheet, column E, for the per-opening breakdown
B11: 3. Interview-to-Offer Ratio
B12: Reached Interview (count) | D12: =COUNTIF(Candidates!$J$2:$J$98,"<>") -> 66
B13: Received Offer (count) | D13: =COUNTIF(Candidates!$K$2:$K$98,"<>") -> 46
B14: Interview-to-Offer Ratio | D14: =D13/D12 -> 0.6969697 | E14: Share of interviewed candidates who got an offer
B16: 4. Offer Acceptance Rate
B17: Offers Extended (count) | D17: =COUNTIF(Candidates!$K$2:$K$98,"<>") -> 46
B18: Offers Accepted (count) | D18: =COUNTIF(Candidates!$L$2:$L$98,"Accepted") -> 41
B19: Offer Acceptance Rate | D19: =D18/D17 -> 0.89130435
B21: 5. Hiring-Source Effectiveness (Hired / Applied, by source)
B22: Source | C22: Applied | D22: Hired | E22: Effectiveness
B23: Career Site | C23: =COUNTIF(Candidates!$D$2:$D$98,B23) -> 14 | D23: =COUNTIFS(Candidates!$D$2:$D$98,B23,Candidates!$Q$2:$Q$98,"Hired") -> 3 | E23: =D23/C23 -> 0.21428571
B24: Indeed | C24: =COUNTIF(Candidates!$D$2:$D$98,B24) -> 33 | D24: =COUNTIFS(Candidates!$D$2:$D$98,B24,Candidates!$Q$2:$Q$98,"Hired") -> 13 | E24: =D24/C24 -> 0.39393939
B25: LinkedIn | C25: =COUNTIF(Candidates!$D$2:$D$98,B25) -> 31 | D25: =COUNTIFS(Candidates!$D$2:$D$98,B25,Candidates!$Q$2:$Q$98,"Hired") -> 14 | E25: =D25/C25 -> 0.4516129
B26: Referral | C26: =COUNTIF(Candidates!$D$2:$D$98,B26) -> 15 | D26: =COUNTIFS(Candidates!$D$2:$D$98,B26,Candidates!$Q$2:$Q$98,"Hired") -> 6 | E26: =D26/C26 -> 0.4
B27: University Fair | C27: =COUNTIF(Candidates!$D$2:$D$98,B27) -> 4 | D27: =COUNTIFS(Candidates!$D$2:$D$98,B27,Candidates!$Q$2:$Q$98,"Hired") -> 3 | E27: =D27/C27 -> 0.75
B29: 6. Recruiter Workload (active candidates currently owned)
B30: Recruiter | C30: Active Candidates | D30: Total Ever Assigned
B31: J. Alvarez | C31: =COUNTIFS(Candidates!$E$2:$E$98,B31,Candidates!$P$2:$P$98,"<>Hired",Candidates!$P$2:$P$98,"<>Rejected") -> 0 | D31: =COUNTIF(Candidates!$E$2:$E$98,B31) -> 21
B32: M. Chen | C32: =COUNTIFS(Candidates!$E$2:$E$98,B32,Candidates!$P$2:$P$98,"<>Hired",Candidates!$P$2:$P$98,"<>Rejected") -> 0 | D32: =COUNTIF(Candidates!$E$2:$E$98,B32) -> 46
B33: S. Patel | C33: =COUNTIFS(Candidates!$E$2:$E$98,B33,Candidates!$P$2:$P$98,"<>Hired",Candidates!$P$2:$P$98,"<>Rejected") -> 0 | D33: =COUNTIF(Candidates!$E$2:$E$98,B33) -> 9
B34: R. Thompson | C34: =COUNTIFS(Candidates!$E$2:$E$98,B34,Candidates!$P$2:$P$98,"<>Hired",Candidates!$P$2:$P$98,"<>Rejected") -> 0 | D34: =COUNTIF(Candidates!$E$2:$E$98,B34) -> 21
B35: K. Osei | C35: =COUNTIFS(Candidates!$E$2:$E$98,B35,Candidates!$P$2:$P$98,"<>Hired",Candidates!$P$2:$P$98,"<>Rejected") -> 0 | D35: =COUNTIF(Candidates!$E$2:$E$98,B35) -> 0
B37: 7. Candidate Drop-off Stage (where rejected candidates exit)
B38: Stage | C38: Rejections | D38: % of All Rejections
B39: Recruiter Review | C39: =COUNTIF(Candidates!$R$2:$R$98,B39) -> 18 | D39: =C39/$C$44 -> 0.31034483
B40: Screening | C40: =COUNTIF(Candidates!$R$2:$R$98,B40) -> 13 | D40: =C40/$C$44 -> 0.22413793
B41: Interview | C41: =COUNTIF(Candidates!$R$2:$R$98,B41) -> 20 | D41: =C41/$C$44 -> 0.34482759
B42: Offer | C42: =COUNTIF(Candidates!$R$2:$R$98,B42) -> 5 | D42: =C42/$C$44 -> 0.086206897
B43: Background Check | C43: =COUNTIF(Candidates!$R$2:$R$98,B43) -> 2 | D43: =C43/$C$44 -> 0.034482759
B44: Total Rejected | C44: =COUNTIF(Candidates!$Q$2:$Q$98,"Rejected") -> 58

Sheet Stage Duration Analysis
B2: Stage Duration Analysis — Where Time Is Lost
B3: Average calendar days spent in each transition, all candidates who reached that stage
B5: Transition | C5: Avg Days | D5: Max Days | E5: Candidates ≥10 days | F5: % Delayed (≥10 days)
B6: Application -> Recruiter Review | C6: =AVERAGE(Candidates!$U$2:$U$98) -> 3.0824742 | D6: =MAX(Candidates!$U$2:$U$98) -> 5 | E6: =COUNTIF(Candidates!$U$2:$U$98,">=10") -> 0 | F6: =E6/COUNT(Candidates!$U$2:$U$98) -> 0
B8: Recruiter Review -> Screening | C8: =AVERAGE(Candidates!$V$2:$V$98) -> 4.3417722 | D8: =MAX(Candidates!$V$2:$V$98) -> 6 | E8: =COUNTIF(Candidates!$V$2:$V$98,">=10") -> 0 | F8: =E8/COUNT(Candidates!$V$2:$V$98) -> 0
B10: Screening -> Interview Scheduled | C10: =AVERAGE(Candidates!$W$2:$W$98) -> 9.0909091 | D10: =MAX(Candidates!$W$2:$W$98) -> 19 | E10: =COUNTIF(Candidates!$W$2:$W$98,">=10") -> 33 | F10: =E10/COUNT(Candidates!$W$2:$W$98) -> 0.5
B12: Interview Scheduled -> Completed | C12: =AVERAGE(Candidates!$X$2:$X$98) -> 3.1212121 | D12: =MAX(Candidates!$X$2:$X$98) -> 6 | E12: =COUNTIF(Candidates!$X$2:$X$98,">=10") -> 0 | F12: =E12/COUNT(Candidates!$X$2:$X$98) -> 0
B14: Interview Completed -> Offer | C14: =AVERAGE(Candidates!$Y$2:$Y$98) -> 5.2826087 | D14: =MAX(Candidates!$Y$2:$Y$98) -> 8 | E14: =COUNTIF(Candidates!$Y$2:$Y$98,">=10") -> 0 | F14: =E14/COUNT(Candidates!$Y$2:$Y$98) -> 0
B16: Offer Extended -> Response | C16: =AVERAGE(Candidates!$Z$2:$Z$98) -> 5.9130435 | D16: =MAX(Candidates!$Z$2:$Z$98) -> 10 | E16: =COUNTIF(Candidates!$Z$2:$Z$98,">=10") -> 4 | F16: =E16/COUNT(Candidates!$Z$2:$Z$98) -> 0.086956522
B18: Offer Accepted -> Background Check | C18: =AVERAGE(Candidates!$AA$2:$AA$98) -> 7.0731707 | D18: =MAX(Candidates!$AA$2:$AA$98) -> 10 | E18: =COUNTIF(Candidates!$AA$2:$AA$98,">=10") -> 8 | F18: =E18/COUNT(Candidates!$AA$2:$AA$98) -> 0.19512195
B20: Background Check -> Hire | C20: =AVERAGE(Candidates!$AB$2:$AB$98) -> 3.6153846 | D20: =MAX(Candidates!$AB$2:$AB$98) -> 5 | E20: =COUNTIF(Candidates!$AB$2:$AB$98,">=10") -> 0 | F20: =E20/COUNT(Candidates!$AB$2:$AB$98) -> 0
B23: Insight:
B24: The 'Screening -> Interview Scheduled' row shows the highest % Delayed. That gap is hiring-manager calendar backlog, not recruiter or candidate delay — it's the highest-leverage fix for reducing overall time-to-hire.
